Workbook

Sheet Data
A1: # | B1: Deal ID | C1: Deal Value | D1: Revenue LTM | E1: EBITDA LTM | F1: Entry Multiple | G1: EBITDA Margin
A2: Deal 1 | B2: =Screening!I2 -> IQTR1942758117 | C2: =Screening!F2 -> 9243.42 | D2: =Screening!L2 -> 30976.85 | E2: =Screening!N2 -> 5335.2 | F2: =C2/E2 -> 1.7325349 | G2: =100*(E2/D2) -> 17.223184
A3: Deal 2 | B3: =Screening!I3 -> IQTR1784746799 | C3: =Screening!F3 -> 72967.49 | D3: =Screening!L3 -> 12945 | E3: =Screening!N3 -> - | F3: =C3/E3 -> #VALUE! | G3: =E3/D3 -> #VALUE!
A4: Deal 3 | B4: =Screening!I4 -> IQTR1860930383 | C4: =Screening!F4 -> - | D4: =Screening!L4 -> 11615.16 | E4: =Screening!N4 -> 534.7 | F4: =C4/E4 -> #VALUE! | G4: =E4/D4 -> 0.046034665
A5: Deal 4 | B5: =Screening!I5 -> IQTR1944075963 | C5: =Screening!F5 -> 3000 | D5: =Screening!L5 -> 6000 | E5: =Screening!N5 -> - | F5: =C5/E5 -> #VALUE! | G5: =E5/D5 -> #VALUE!
A6: Deal 5 | B6: =Screening!I6 -> IQTR1867916120 | C6: =Screening!F6 -> 15396.69 | D6: =Screening!L6 -> 5564.5 | E6: =Screening!N6 -> 689.8 | F6: =C6/E6 -> 22.320513 | G6: =100*(E6/D6) -> 12.396442
A7: Deal 6 | B7: =Screening!I7 -> IQTR1912024769 | C7: =Screening!F7 -> - | D7: =Screening!L7 -> 5330.6 | E7: =Screening!N7 -> 776.9 | F7: =C7/E7 -> #VALUE! | G7: =E7/D7 -> 0.14574344
A8: Deal 7 | B8: =Screening!I8 -> IQTR1776383559 | C8: =Screening!F8 -> 478.06 | D8: =Screening!L8 -> 5157.45 | E8: =Screening!N8 -> 698.6 | F8: =C8/E8 -> 0.68431148 | G8: =100*(E8/D8) -> 13.545454
A9: Deal 8 | B9: =Screening!I9 -> IQTR1967911118 | C9: =Screening!F9 -> 4359.34 | D9: =Screening!L9 -> 4836.99 | E9: =Screening!N9 -> 766.3 | F9: =C9/E9 -> 5.6888164 | G9: =100*(E9/D9) -> 15.842497
A10: Deal 9 | B10: =Screening!I10 -> IQTR1955725309 | C10: =Screening!F10 -> 141.01 | D10: =Screening!L10 -> 4825.83 | E10: =Screening!N10 -> 10.6 | F10: =C10/E10 -> 13.30283 | G10: =100*(E10/D10) -> 0.21965133
A11: Deal 10 | B11: =Screening!I11 -> IQTR1863840995 | C11: =Screening!F11 -> - | D11: =Screening!L11 -> 4475 | E11: =Screening!N11 -> 776.9 | F11: =C11/E11 -> #VALUE! | G11: =E11/D11 -> 0.17360894
A12: Deal 11 | B12: =Screening!I12 -> IQTR1862954563 | C12: =Screening!F12 -> 129.05 | D12: =Screening!L12 -> 4475 | E12: =Screening!N12 -> 776.9 | F12: =C12/E12 -> 0.16610889 | G12: =100*(E12/D12) -> 17.360894
A13: Deal 12 | B13: =Screening!I13 -> IQTR1838306852 | C13: =Screening!F13 -> 70.67 | D13: =Screening!L13 -> 4301.36 | E13: =Screening!N13 -> 776.9 | F13: =C13/E13 -> 0.090964088 | G13: =100*(E13/D13) -> 18.061729
A14: Deal 13 | B14: =Screening!I14 -> IQTR1929482728 | C14: =Screening!F14 -> 174 | D14: =Screening!L14 -> 4145.17 | E14: =Screening!N14 -> 668.9 | F14: =C14/E14 -> 0.26012857 | G14: =100*(E14/D14) -> 16.136853
A15: Deal 14 | B15: =Screening!I15 -> IQTR1850957260 | C15: =Screening!F15 -> 1678.11 | D15: =Screening!L15 -> 4057.13 | E15: =Screening!N15 -> - | F15: =C15/E15 -> #VALUE! | G15: =E15/D15 -> #VALUE!
A16: Deal 15 | B16: =Screening!I16 -> IQTR1785931677 | C16: =Screening!F16 -> 66.77 | D16: =Screening!L16 -> 3926.97 | E16: =Screening!N16 -> 776.9 | F16: =C16/E16 -> 0.085944137 | G16: =100*(E16/D16) -> 19.783701
A17: Deal 16 | B17: =Screening!I17 -> IQTR1856318900 | C17: =Screening!F17 -> 30998.87 | D17: =Screening!L17 -> 3842.97 | E17: =Screening!N17 -> - | F17: =C17/E17 -> #VALUE! | G17: =E17/D17 -> #VALUE!
A18: Deal 17 | B18: =Screening!I18 -> IQTR1762042686 | C18: =Screening!F18 -> 102.35 | D18: =Screening!L18 -> 3841.83 | E18: =Screening!N18 -> 776.9 | F18: =C18/E18 -> 0.13174154 | G18: =100*(E18/D18) -> 20.222134
A19: Deal 18 | B19: =Screening!I19 -> IQTR1816233358 | C19: =Screening!F19 -> 45.4 | D19: =Screening!L19 -> 3694.6 | E19: =Screening!N19 -> 776.9 | F19: =C19/E19 -> 0.058437379 | G19: =100*(E19/D19) -> 21.027987
A20: Deal 19 | B20: =Screening!I20 -> IQTR1680643570 | C20: =Screening!F20 -> - | D20: =Screening!L20 -> 3311.12 | E20: =Screening!N20 -> 396 | F20: =C20/E20 -> #VALUE! | G20: =E20/D20 -> 0.11959699
A21: Deal 20 | B21: =Screening!I21 -> IQTR1765987121 | C21: =Screening!F21 -> 17182.11 | D21: =Screening!L21 -> 3217.17 | E21: =Screening!N21 -> - | F21: =C21/E21 -> #VALUE! | G21: =E21/D21 -> #VALUE!
A22: Deal 21 | B22: =Screening!I22 -> IQTR1853829677 | C22: =Screening!F22 -> - | D22: =Screening!L22 -> 3164.63 | E22: =Screening!N22 -> 396 | F22: =C22/E22 -> #VALUE! | G22: =E22/D22 -> 0.12513311
A23: Deal 22 | B23: =Screening!I23 -> IQTR1798157276 | C23: =Screening!F23 -> 6477.38 | D23: =Screening!L23 -> 2743.8 | E23: =Screening!N23 -> - | F23: =C23/E23 -> #VALUE! | G23: =E23/D23 -> #VALUE!
A24: Deal 23 | B24: =Screening!I24 -> IQTR1821576629 | C24: =Screening!F24 -> - | D24: =Screening!L24 -> 2659.43 | E24: =Screening!N24 -> 282.7 | F24: =C24/E24 -> #VALUE! | G24: =E24/D24 -> 0.10630097
A25: Deal 24 | B25: =Screening!I25 -> IQTR1868555623 | C25: =Screening!F25 -> 35791.48 | D25: =Screening!L25 -> 2583.1 | E25: =Screening!N25 -> 878 | F25: =C25/E25 -> 40.764784 | G25: =100*(E25/D25) -> 33.990167
A26: Deal 25 | B26: =Screening!I26 -> IQTR1902207620 | C26: =Screening!F26 -> 702 | D26: =Screening!L26 -> 2390.56 | E26: =Screening!N26 -> 209 | F26: =C26/E26 -> 3.3588517 | G26: =100*(E26/D26) -> 8.7427214
A27: Deal 26 | B27: =Screening!I27 -> IQTR1681724164 | C27: =Screening!F27 -> - | D27: =Screening!L27 -> 2377.81 | E27: =Screening!N27 -> 759.9 | F27: =C27/E27 -> #VALUE! | G27: =E27/D27 -> 0.31957978
A28: Deal 27 | B28: =Screening!I28 -> IQTR1890818396 | C28: =Screening!F28 -> 1239.77 | D28: =Screening!L28 -> 2178.56 | E28: =Screening!N28 -> 184.6 | F28: =C28/E28 -> 6.7159805 | G28: =100*(E28/D28) -> 8.4734871
A29: Deal 28 | B29: =Screening!I29 -> IQTR1802771200 | C29: =Screening!F29 -> - | D29: =Screening!L29 -> 2177.1 | E29: =Screening!N29 -> 282.7 | F29: =C29/E29 -> #VALUE! | G29: =E29/D29 -> 0.12985164
A30: Deal 29 | B30: =Screening!I30 -> IQTR1685463254 | C30: =Screening!F30 -> 2500 | D30: =Screening!L30 -> 2035 | E30: =Screening!N30 -> - | F30: =C30/E30 -> #VALUE! | G30: =E30/D30 -> #VALUE!
A31: Deal 30 | B31: =Screening!I31 -> IQTR1904331229 | C31: =Screening!F31 -> 2987.11 | D31: =Screening!L31 -> 2019.35 | E31: =Screening!N31 -> 184.6 | F31: =C31/E31 -> 16.181528 | G31: =100*(E31/D31) -> 9.1415555
A32: Deal 31 | B32: =Screening!I32 -> IQTR1773626089 | C32: =Screening!F32 -> - | D32: =Screening!L32 -> 2000 | E32: =Screening!N32 -> - | F32: =C32/E32 -> #VALUE! | G32: =E32/D32 -> #VALUE!
A33: Deal 32 | B33: =Screening!I33 -> IQTR1757348954 | C33: =Screening!F33 -> 20862.21 | D33: =Screening!L33 -> 1826 | E33: =Screening!N33 -> - | F33: =C33/E33 -> #VALUE! | G33: =E33/D33 -> #VALUE!
A34: Deal 33 | B34: =Screening!I34 -> IQTR1930420741 | C34: =Screening!F34 -> 1010.8 | D34: =Screening!L34 -> 1801.51 | E34: =Screening!N34 -> 100.2 | F34: =C34/E34 -> 10.087824 | G34: =100*(E34/D34) -> 5.5620008
A35: Deal 34 | B35: =Screening!I35 -> IQTR1772509697 | C35: =Screening!F35 -> 291.2 | D35: =Screening!L35 -> 1766.63 | E35: =Screening!N35 -> - | F35: =C35/E35 -> #VALUE! | G35: =E35/D35 -> #VALUE!
A36: Deal 35 | B36: =Screening!I36 -> IQTR1777417497 | C36: =Screening!F36 -> 8340.71 | D36: =Screening!L36 -> 1756.5 | E36: =Screening!N36 -> - | F36: =C36/E36 -> #VALUE! | G36: =E36/D36 -> #VALUE!
A37: Deal 36 | B37: =Screening!I37 -> IQTR1818826920 | C37: =Screening!F37 -> 6570.02 | D37: =Screening!L37 -> 1747 | E37: =Screening!N37 -> - | F37: =C37/E37 -> #VALUE! | G37: =E37/D37 -> #VALUE!
A38: Deal 37 | B38: =Screening!I38 -> IQTR1760525650 | C38: =Screening!F38 -> - | D38: =Screening!L38 -> 1734.66 | E38: =Screening!N38 -> - | F38: =C38/E38 -> #VALUE! | G38: =E38/D38 -> #VALUE!
A39: Deal 38 | B39: =Screening!I39 -> IQTR1945143029 | C39: =Screening!F39 -> 10097.75 | D39: =Screening!L39 -> 1655.31 | E39: =Screening!N39 -> 280.9 | F39: =C39/E39 -> 35.947846 | G39: =100*(E39/D39) -> 16.969631
A40: Deal 39 | B40: =Screening!I40 -> IQTR1888824933 | C40: =Screening!F40 -> 803.5 | D40: =Screening!L40 -> 1613.63 | E40: =Screening!N40 -> - | F40: =C40/E40 -> #VALUE! | G40: =E40/D40 -> #VALUE!
...

Sheet BENCHMARKS
B1: Revenue LTM | C1: EBITDA LTM | D1: Entry Multiple | E1: EBITDA Margin | G1: Count | H1: # | I1: Deal ID | J1: Deal Value | K1: Revenue LTM | L1: EBITDA LTM | M1: Entry Multiple | N1: EBITDA Margin
A2: Median | B2: =MEDIAN(K2:K26) -> 288.9 | C2: =MEDIAN(L2:L26) -> 45.4 | D2: =MEDIAN(M2:M26) -> 10.533333 | E2: =MEDIAN(N2:N26) -> 17.029725 | G2: 1 | H2: Deal 8 | I2: IQTR1967911118 | J2: 4359.34 | K2: 4836.99 | L2: 766.3 | M2: 5.6888164 | N2: 15.842497
A3: Mean | B3: =AVERAGE(K2:K26) -> 593.3944 | C3: =AVERAGE(L2:L26) -> 131.9452 | D3: =AVERAGE(M2:M26) -> 10.274033 | E3: =AVERAGE(N2:N26) -> 21.434774 | G3: 2 | H3: Deal 44 | I3: IQTR1903250285 | J3: 1967.76 | K3: 1484.46 | L3: 167 | M3: 11.782994 | N3: 11.249882
A4: 25th percentile | B4: =QUARTILE(K2:K26,1) -> 88.23 | C4: =QUARTILE(L2:L26,1) -> 29.3 | D4: =QUARTILE(M2:M26,1) -> 6.7617433 | E4: =QUARTILE(N2:N26,1) -> 13.016453 | G4: 3 | H4: Deal 49 | I4: IQTR1781913531 | J4: 7543.48 | K4: 1386.92 | L4: 750.3 | M4: 10.053952 | N4: 54.09829
A5: 75th percentile | B5: =QUARTILE(K2:K26,3) -> 552.52 | C5: =QUARTILE(L2:L26,3) -> 93.5 | D5: =QUARTILE(M2:M26,3) -> 13.549267 | E5: =QUARTILE(N2:N26,3) -> 27.706844 | G5: 4 | H5: Deal 56 | I5: IQTR1903107882 | J5: 7350.58 | K5: 1140.44 | L5: 437.4 | M5: 16.805167 | N5: 38.353618
A6: Min | B6: =MIN(K2:K26) -> 54.7 | C6: =MIN(L2:L26) -> 7.12 | D6: =MIN(M2:M26) -> 4.4775281 | E6: =MIN(N2:N26) -> 10.00834 | G6: 5 | H6: Deal 76 | I6: IQTR1930453238 | J6: 4678.82 | K6: 796.9 | L6: 273.5 | M6: 17.107203 | N6: 34.320492
A7: Max | B7: =MAX(K2:K26) -> 4836.99 | C7: =MAX(L2:L26) -> 766.3 | D7: =MAX(M2:M26) -> 17.107203 | E7: =MAX(N2:N26) -> 54.09829 | G7: 6 | H7: Deal 96 | I7: IQTR1913479166 | J7: 1254.54 | K7: 662.29 | L7: 81.9 | M7: 15.317949 | N7: 12.366184
A8: Count | B8: =COUNT(K2:K26) -> 25 | C8: =COUNT(L2:L26) -> 25 | D8: =COUNT(M2:M26) -> 25 | E8: =COUNT(N2:N26) -> 25 | G8: 7 | H8: Deal 120 | I8: IQTR1934842365 | J8: 808.96 | K8: 552.52 | L8: 76.8 | M8: 10.533333 | N8: 13.899949
G9: 8 | H9: Deal 121 | I9: IQTR1956594929 | J9: 1434.05 | K9: 549.04 | L9: 93.5 | M9: 15.337433 | N9: 17.029725
G10: 9 | H10: Deal 129 | I10: IQTR1848494184 | J10: 310.25 | K10: 482.88 | L10: 54.6 | M10: 5.6822344 | N10: 11.307157
G11: 10 | H11: Deal 135 | I11: IQTR1848560033 | J11: 739.79 | K11: 463.96 | L11: 54.6 | M11: 13.549267 | N11: 11.768256
G12: 11 | H12: Deal 161 | I12: IQTR1889524439 | J12: 522.1 | K12: 345.14 | L12: 45.4 | M12: 11.5 | N12: 13.154082
G13: 12 | H13: Deal 181 | I13: IQTR1969539143 | J13: 900.9 | K13: 306.53 | L13: 125.7 | M13: 7.1670644 | N13: 41.007405
G14: 13 | H14: Deal 189 | I14: IQTR1913989358 | J14: 444.57 | K14: 288.9 | L14: 83.5 | M14: 5.3241916 | N14: 28.902735
G15: 14 | H15: Deal 197 | I15: IQTR1962910014 | J15: 319.98 | K15: 273.57 | L15: 35.7 | M15: 8.9630252 | N15: 13.049676
G16: 15 | H16: Deal 225 | I16: IQTR1914744113 | J16: 279.26 | K16: 225.74 | L16: 41.3 | M16: 6.7617433 | N16: 18.295384
G17: 16 | H17: Deal 257 | I17: IQTR1815364960 | J17: 184.55 | K17: 192.01 | L17: 40.5 | M17: 4.5567901 | N17: 21.092651
G18: 17 | H18: Deal 283 | I18: IQTR1973020838 | J18: 297.14 | K18: 170.91 | L18: 32.6 | M18: 9.1147239 | N18: 19.074367
G19: 18 | H19: Deal 323 | I19: IQTR2000108346 | J19: 440.08 | K19: 139.54 | L19: 29.3 | M19: 15.019795 | N19: 20.997563
G20: 19 | H20: Deal 414 | I20: IQTR1930066296 | J20: 139.46 | K20: 88.23 | L20: 12.2 | M20: 11.431148 | N20: 13.827496
... G26: 25 | H26: Deal 525 | I26: IQTR1963039166 | J26: 31.88 | K26: 54.7 | L26: 7.12 | M26: 4.4775281 | N26: 13.016453

Sheet Screening
A1: All Transactions Announced Date | B1: Target/Issuer | C1: Exchange:Ticker | D1: Transaction Types | E1: Transaction Status | F1: Total Transaction Value ($USDmm, Historical rate) | G1: Buyers/Investors | H1: Sellers | I1: CIQ Transaction ID | J1: M&A Announced Date | K1: Industry Classifications [Target/Issuer] | L1: Target/Issuer LTM Financials - Total Revenue (at Announcement) ($USDmm, Historical rate) | M1: M&A Closed Date | N1: EBITDA [LTM] ($USDmm, Historical rate) [Target/Issuer] | O1: Merger/Acquisition Features
A2: 2025-05-08 | B2: NTT DATA Group Corporation | C2: - | D2: Merger/Acquisition | E2: Closed | F2: 9243.42 | G2: - | H2: - | I2: IQTR1942758117 | J2: 2025-05-08 | K2: Software and Services (Primary) | L2: 30976.85 | M2: 2025-06-19 | N2: 5335.2 | O2: Acquisition of Minority Stake; Cash Merger; Going Private Transaction; Majority Shareholder Increasing Ownership Stake; Majority Shareholder Purchasing Remaining Shares; Squeeze Out / Short Form Merger; Tender Offer; Tender Offer (Full Bid)
A3: 2022-05-26 | B3: VMware LLC | C3: - | D3: Merger/Acquisition | E3: Closed | F3: 72967.49 | G3: Broadcom Inc. (NasdaqGS:AVGO) | H3: Silver Lake Technology Management, L.L.C.; Dodge & Cox; Silver Lake Partners V DE (AIV), L.P. | I3: IQTR1784746799 | J3: 2022-05-26 | K3: Software and Services (Primary) | L3: 12945 | M3: 2023-11-22 | N3: - | O3: Acquisition of Majority Stake; Go Shop Provision
A4: 2023-11-02 | B4: Atos Group (ENXTPA:ATO) | C4: ENXTPA:ATO | D4: Merger/Acquisition | E4: Closed | F4: - | G4: Onepoint SAS | H4: - | I4: IQTR1860930383 | J4: 2023-11-02 | K4: Software and Services (Primary) | L4: 11615.16 | M4: 2023-11-02 | N4: 534.7 | O4: Acquisition of Minority Stake; Terms Not Disclosed
A5: 2025-05-19 | B5: DataCenter Infrastructure Manufacturing Business of ZT Group Intl, Inc. | C5: - | D5: Merger/Acquisition | E5: Closed | F5: 3000 | G5: Sanmina Corporation (NasdaqGS:SANM) | H5: ZT Group Intl, Inc. | I5: IQTR1944075963 | J5: 2025-05-19 | K5: Software and Services (Primary) | L5: 6000 | M5: 2025-10-27 | N5: - | O5: Acquisition of Majority Stake; Corporate Divestiture; Earnout Payments
A6: 2024-01-09 | B6: Juniper Networks, Inc. | C6: - | D6: Merger/Acquisition | E6: Closed | F6: 15396.69 | G6: Hewlett Packard Enterprise Company (NYSE:HPE) | H6: - | I6: IQTR1867916120 | J6: 2024-01-09 | K6: Software and Services (Primary) | L6: 5564.5 | M6: 2025-07-02 | N6: 689.8 | O6: Acquisition of Majority Stake; Cash Merger
A7: 2024-12-05 | B7: Indra Sistemas, S.A. (BME:IDR) | C7: BME:IDR | D7: Merger/Acquisition | E7: Closed | F7: - | G7: Escribano Mechanical And Engineering, S.L. | H7: - | I7: IQTR1912024769 | J7: 2024-12-05 | K7: Software and Services (Primary) | L7: 5330.6 | M7: 2024-12-05 | N7: 776.9 | O7: Acquisition of Minority Stake; Minority Shareholder Increasing Ownership Stake; Terms Not Disclosed
A8: 2022-03-23 | B8: Nomura Research Institute, Ltd. (TSE:4307) | C8: TSE:4307 | D8: Merger/Acquisition | E8: Closed | F8: 478.06 | G8: - | H8: Nomura Holdings, Inc. (TSE:8604) | I8: IQTR1776383559 | J8: 2022-03-23 | K8: Software and Services (Primary) | L8: 5157.45 | M8: 2022-03-23 | N8: 698.6 | O8: Acquisition of Minority Stake
A9: 2025-10-29 | B9: SCSK Corporation | C9: - | D9: Merger/Acquisition | E9: Closed | F9: 4359.34 | G9: Sumitomo Corporation (TSE:8053) | H9: ARGO GRAPHICS Inc. (TSE:7595); State Street Bank & Trust Company 505001; State Street Bank and Trust Company 510312; Government Of Norway; State Street Bank West Client - Treaty 505234; Custody Bank of Japan, Ltd. (Trust Account); The Master Trust Bank of Japan, Ltd. (Trust Account); Custody Bank of Japan, Ltd. (Trust Account 4) | I9: IQTR1967911118 | J9: 2025-10-29 | K9: Software and Services (Primary) | L9: 4836.99 | M9: 2025-12-12 | N9: 766.3 | O9: Acquisition of Minority Stake; Majority Shareholder Increasing Ownership Stake; Tender Offer; Tender Offer (Full Bid)
A10: 2025-08-04 | B10: iSoftStone Information Technology (Group) Co., Ltd. (SZSE:301236) | C10: SZSE:301236 | D10: Merger/Acquisition | E10: Closed | F10: 141.01 | G10: UBS Group AG (SWX:UBSG); Morgan Stanley & Co. International plc; Guotai Haitong Securities Co., Ltd. (SHSE:601211); J.P. Morgan Securities plc; GF Securities Co., Ltd. (SZSE:000776); Sealand Securities Co., Ltd. (SZSE:000750); China Asset Management Co. Ltd.; E Fund Management Co., Ltd.; Nuode Asset Management Co., Ltd.; Caitong Fund Management Co., Ltd.; Dajia Asset Management Co., Ltd.; Zhong Ou Fund Management Co., Ltd; Shanghai Muxin Private Fund Management Co., Ltd.; Yingshui Investment Co., Ltd.; Shenzhen Commando Capital Management Co., Ltd.; Hangzhou Lexin Investment Management Co., Ltd.; Hunan Chasing Asset Management Co.,Ltd.; Nanjing Shengquan Hengyuan Investment Co., Ltd.; Ningbo Meishan Bonded Port Lingding Investment Management Co., Ltd.; Qingdao Luxiu Investment Management Co., Ltd.; Shanghai Qinsheng Private Fund Management Co., Ltd.; Zhijian (Shaoxing Keqiao) Private Equity Fund Management Co., Ltd.; Beijing Pingfan Private Equity Fund Management Co., Ltd.; Huaan Securities Asset Management Co., Ltd.; Chengdu Fuende Tongchuang Asset Management Co., Ltd; Shanghai Dunyuan Private Equity Fund Management Co., Ltd; Beijing Yuexi Private Fund Management Co., Ltd; Xiamen Fengqiaolin Private Fund Management Co., Ltd | H10: FNOF Easynet (HK) Limited | I10: IQTR1955725309 | J10: 2025-08-04 | K10: Software and Services (Primary) | L10: 4825.83 | M10: 2025-08-04 | N10: 10.6 | O10: Acquisition of Minority Stake; Cross-Border
A11: 2023-11-30 | B11: Indra Sistemas, S.A. (BME:IDR) | C11: BME:IDR | D11: Merger/Acquisition | E11: Closed | F11: - | G11: JPMorgan Chase & Co. (NYSE:JPM) | H11: - | I11: IQTR1863840995 | J11: 2023-11-30 | K11: Software and Services (Primary) | L11: 4475 | M11: 2023-11-30 | N11: 776.9 | O11: Acquisition of Minority Stake; Cross-Border
A12: 2023-11-24 | B12: Indra Sistemas, S.A. (BME:IDR) | C12: BME:IDR | D12: Merger/Acquisition | E12: Closed | F12: 129.05 | G12: Escribano Mechanical And Engineering, S.L. | H12: JPMorgan Chase & Co. (NYSE:JPM) | I12: IQTR1862954563 | J12: 2023-11-24 | K12: Software and Services (Primary) | L12: 4475 | M12: 2023-11-24 | N12: 776.9 | O12: Acquisition of Minority Stake; Minority Shareholder Increasing Ownership Stake
A13: 2023-05-15 | B13: Indra Sistemas, S.A. (BME:IDR) | C13: BME:IDR | D13: Merger/Acquisition | E13: Closed | F13: 70.67 | G13: Escribano Mechanical And Engineering, S.L. | H13: - | I13: IQTR1838306852 | J13: 2023-05-15 | K13: Software and Services (Primary) | L13: 4301.36 | M13: 2023-05-15 | N13: 776.9 | O13: Acquisition of Minority Stake
A14: 2025-01-31 | B14: Asseco Poland S.A. (WSE:ACP) | C14: WSE:ACP | D14: Merger/Acquisition | E14: Closed | F14: 174 | G14: Yukon Niebieski Kapital B.V. | H14: Cyfrowy Polsat S.A. (WSE:CPS) | I14: IQTR1929482728 | J14: 2025-01-31 | K14: Software and Services (Primary) | L14: 4145.17 | M14: 2025-01-31 | N14: 668.9 | O14: Acquisition of Minority Stake; Cross-Border
A15: 2023-08-02 | B15: ITOCHU Techno-Solutions Corporation | C15: - | D15: Merger/Acquisition | E15: Closed | F15: 1678.11 | G15: ITOCHU Corporation (TSE:8001) | H15: - | I15: IQTR1850957260 | J15: 2023-08-02 | K15: Software and Services (Primary) | L15: 4057.13 | M15: 2023-09-14 | N15: - | O15: Acquisition of Minority Stake; Majority Shareholder Increasing Ownership Stake; Tender Offer; Tender Offer (Full Bid)
A16: 2022-06-03 | B16: Indra Sistemas, S.A. (BME:IDR) | C16: BME:IDR | D16: Merger/Acquisition | E16: Closed | F16: 66.77 | G16: SAPA Placencia Holding, S.L. | H16: Corporación Financiera Alba, S.A. | I16: IQTR1785931677 | J16: 2022-06-03 | K16: Software and Services (Primary) | L16: 3926.97 | M16: 2022-06-03 | N16: 776.9 | O16: Acquisition of Minority Stake
A17: 2023-09-21 | B17: Splunk Inc. | C17: - | D17: Merger/Acquisition | E17: Closed | F17: 30998.87 | G17: Cisco Systems, Inc. (NasdaqGS:CSCO) | H17: Hellman & Friedman LLC; Silver Lake Technology Management, L.L.C.; BlackRock, Inc. (NYSE:BLK); The Vanguard Group, Inc.; PRIMECAP Management Company | I17: IQTR1856318900 | J17: 2023-09-21 | K17: Software and Services (Primary) | L17: 3842.97 | M17: 2024-03-18 | N17: - | O17: Acquisition of Majority Stake; Cash Merger
A18: 2021-12-14 | B18: Indra Sistemas, S.A. (BME:IDR) | C18: BME:IDR | D18: Merger/Acquisition | E18: Closed | F18: 102.35 | G18: SAPA Placencia Holding, S.L. | H18: Corporación Financiera Alba, S.A. | I18: IQTR1762042686 | J18: 2021-12-14 | K18: Software and Services (Primary) | L18: 3841.83 | M18: 2021-12-14 | N18: 776.9 | O18: Acquisition of Minority Stake
A19: 2022-11-23 | B19: Indra Sistemas, S.A. (BME:IDR) | C19: BME:IDR | D19: Merger/Acquisition | E19: Closed | F19: 45.4 | G19: Goldman Sachs (Singapore) Pte | H19: - | I19: IQTR1816233358 | J19: 2022-11-23 | K19: Software and Services (Primary) | L19: 3694.6 | M19: 2022-11-23 | N19: 776.9 | O19: Acquisition of Minority Stake; Cross-Border; Minority Shareholder Increasing Ownership Stake
A20: 2021-09-08 | B20: Tieto Oyj (HLSE:TIETO) | C20: HLSE:TIETO | D20: Merger/Acquisition | E20: Closed | F20: - | G20: - | H20: - | I20: IQTR1680643570 | J20: 2021-09-08 | K20: Software and Services (Primary) | L20: 3311.12 | M20: 2021-09-08 | N20: 396 | O20: Acquisition of Minority Stake; Terms Not Disclosed
A21: 2022-01-31 | B21: Citrix Systems, Inc. | C21: - | D21: Merger/Acquisition | E21: Closed | F21: 17182.11 | G21: Cloud Software Group, Inc. | H21: BlackRock, Inc. (NYSE:BLK); The Vanguard Group, Inc.; Elliott Management Corporation; T. Rowe Price Associates, Inc. | I21: IQTR1765987121 | J21: 2022-01-31 | K21: Software and Services (Primary) | L21: 3217.17 | M21: 2022-09-30 | N21: - | O21: Acquisition of Majority Stake; Cash Merger; Going Private Transaction; Leveraged Buy Out (LBO)
A22: 2023-08-25 | B22: Tieto Oyj (HLSE:TIETO) | C22: HLSE:TIETO | D22: Merger/Acquisition | E22: Closed | F22: - | G22: Silchester International Investors LLP | H22: - | I22: IQTR1853829677 | J22: 2023-08-25 | K22: Software and Services (Primary) | L22: 3164.63 | M22: 2023-08-24 | N22: 396 | O22: Acquisition of Minority Stake; Cross-Border; Minority Shareholder Increasing Ownership Stake; Terms Not Disclosed
A23: 2022-08-25 | B23: Micro Focus International Limited | C23: - | D23: Merger/Acquisition | E23: Closed | F23: 6477.38 | G23: Open Text Corporation (NasdaqGS:OTEX) | H23: Dodge & Cox | I23: IQTR1798157276 | J23: 2022-08-25 | K23: Software and Services (Primary) | L23: 2743.8 | M23: 2023-01-31 | N23: - | O23: Acquisition of Majority Stake; Cash Merger; Cross-Border
A24: 2023-01-11 | B24: Sinch AB (publ) (OM:SINCH) | C24: OM:SINCH | D24: Merger/Acquisition | E24: Closed | F24: - | G24: Swedbank Robur Fonder AB | H24: - | I24: IQTR1821576629 | J24: 2023-01-11 | K24: Software and Services (Primary) | L24: 2659.43 | M24: 2022-12-31 | N24: 282.7 | O24: Acquisition of Minority Stake; Terms Not Disclosed
A25: 2024-01-16 | B25: ANSYS, Inc. | C25: - | D25: Merger/Acquisition | E25: Closed | F25: 35791.48 | G25: Synopsys, Inc. (NasdaqGS:SNPS) | H25: BlackRock, Inc. (NYSE:BLK); The Vanguard Group, Inc. | I25: IQTR1868555623 | J25: 2024-01-16 | K25: Software and Services (Primary) | L25: 2583.1 | M25: 2025-07-17 | N25: 878 | O25: Acquisition of Majority Stake
A26: 2024-10-29 | B26: NEC Networks & System Integration Corporation | C26: - | D26: Merger/Acquisition | E26: Closed | F26: 702 | G26: NEC Corporation (TSE:6701) | H26: Sumitomo Realty & Development Co., Ltd. (TSE:8830); The Master Trust Bank of Japan, Ltd.; Norway; State Street Bank and Trust Company 510312; BNY GCM CLIENT ACCOUNT JPRD AC ISG (FE-AC); JP Morgan Chase Bank 385632; Custody Bank of Japan, Ltd. (Trust Account); Employees’ Stock Ownership Plan of NEC Networks & System | I26: IQTR1902207620 | J26: 2024-10-29 | K26: Software and Services (Primary) | L26: 2390.56 | M26: 2025-01-10 | N26: 209 | O26: Acquisition of Minority Stake; Majority Shareholder Increasing Ownership Stake; Tender Offer; Tender Offer (Partial Bid)
A27: 2021-09-09 | B27: Visma AS | C27: - | D27: Merger/Acquisition | E27: Closed | F27: - | G27: GIC Private Limited; Folketrygdfondet; Aeternum Management AS; Vind Group | H27: - | I27: IQTR1681724164 | J27: 2021-09-09 | K27: Software and Services (Primary) | L27: 2377.81 | M27: 2021-09-09 | N27: 759.9 | O27: Acquisition of Minority Stake; Cross-Border; Terms Not Disclosed
A28: 2024-08-08 | B28: Fuji Soft Incorporated | C28: - | D28: Merger/Acquisition | E28: Closed | F28: 1239.77 | G28: KKR & Co. Inc. (NYSE:KKR) | H28: Farallon Capital Management, L.L.C.; Custody Bank of Japan, Ltd.; The Master Trust Bank of Japan, Ltd.; State Street Bank And Trust Company; Yugen Kaisha NFC; 3D Investment Partners Pte. Ltd; Goldman Sachs & Co. REG; Cabrillo Funding Ltd. | I28: IQTR1890818396 | J28: 2024-08-08 | K28: Software and Services (Primary) | L28: 2178.56 | M28: 2024-11-05 | N28: 184.6 | O28: Acquisition of Minority Stake; Cross-Border; Tender Offer; Tender Offer (Full Bid)
A29: 2022-09-29 | B29: Sinch AB (publ) (OM:SINCH) | C29: OM:SINCH | D29: Merger/Acquisition | E29: Closed | F29: - | G29: Neqst D2 AB | H29: SoftBank Corp. (TSE:9434) | I29: IQTR1802771200 | J29: 2022-09-29 | K29: Software and Services (Primary) | L29: 2177.1 | M29: 2022-09-29 | N29: 282.7 | O29: Acquisition of Minority Stake; Management Participated; Minority Shareholder Increasing Ownership Stake; Terms Not Disclosed
A30: 2021-10-18 | B30: Sirius Computer Solutions, LLC. | C30: - | D30: Merger/Acquisition | E30: Closed | F30: 2500 | G30: CDW LLC | H30: Clayton, Dubilier & Rice, LLC | I30: IQTR1685463254 | J30: 2021-10-18 | K30: Software and Services (Primary) | L30: 2035 | M30: 2021-12-01 | N30: - | O30: Acquisition of Majority Stake; Cash Merger
A31: 2024-11-15 | B31: Fuji Soft Incorporated | C31: - | D31: Merger/Acquisition | E31: Closed | F31: 2987.11 | G31: KKR & Co. Inc. (NYSE:KKR) | H31: Custody Bank of Japan, Ltd.; Tokyo Century Corporation (TSE:8439); The Master Trust Bank of Japan, Ltd.; State Street Bank And Trust Company; Yugen Kaisha NFC; The Hongkong And Shanghai Banking Corp. Ltd. Tokyo Branch; Goldman Sachs & Co. REG; Cabrillo Funding Ltd. | I31: IQTR1904331229 | J31: 2024-11-15 | K31: Software and Services (Primary) | L31: 2019.35 | M31: 2025-02-19 | N31: 184.6 | O31: Acquisition of Majority Stake; Cash Merger; Cross-Border; Going Private Transaction; Leveraged Buy Out (LBO); Minority Shareholder Increasing Ownership Stake; Minority Shareholder Purchasing Remaining Shares; Squeeze Out / Short Form Merger; Tender Offer; Tender Offer (Full Bid)
A32: 2022-03-07 | B32: vCORE Technology Partners, LLC | C32: - | D32: Merger/Acquisition | E32: Closed | F32: - | G32: AHEAD, Inc. | H32: - | I32: IQTR1773626089 | J32: 2022-03-07 | K32: Software and Services (Primary) | L32: 2000 | M32: 2022-03-07 | N32: - | O32: Acquisition of Majority Stake; Terms Not Disclosed
A33: 2021-11-08 | B33: McAfee Corp. | C33: - | D33: Merger/Acquisition | E33: Closed | F33: 20862.21 | G33: Advent International, L.P.; Permira Advisers Ltd.; GIC Private Limited; Canada Pension Plan Investment Board; Abu Dhabi Investment Authority; Crosspoint Capital Partners, LP | H33: McAfee, LLC; TPG Global, LLC; TPG VII Manta AIV Co-Invest, L.P.; TPG VII Manta Blocker Co-Invest I, L.P.; TPG VII Manta AIV I, L.P.; TPG VII Manta Holdings II, L.P.; TPG VII Side-by-Side Separate Account I, L.P. | I33: IQTR1757348954 | J33: 2021-11-08 | K33: Software and Services (Primary) | L33: 1826 | M33: 2022-03-01 | N33: - | O33: Acquisition of Majority Stake; Cash Merger; Cross-Border; Go Shop Provision; Going Private Transaction
A34: 2025-02-07 | B34: Converge Technology Solutions Corp. | C34: - | D34: Merger/Acquisition | E34: Closed | F34: 1010.8 | G34: Mainline Information Systems, LLC | H34: Mawer Investment Management Ltd.; Mcmillan Family Foundation; 2491626 Ontario Inc.; Acoma Investments Limited | I34: IQTR1930420741 | J34: 2025-02-07 | K34: Software and Services (Primary) | L34: 1801.51 | M34: 2025-04-22 | N34: 100.2 | O34: Acquisition of Majority Stake; Cash Merger; Consolidation/Roll Up; Cross-Border; Going Private Transaction
A35: 2022-02-24 | B35: AKKA Technologies SE | C35: - | D35: Merger/Acquisition | E35: Closed | F35: 291.2 | G35: Akkodis Group AG | H35: - | I35: IQTR1772509697 | J35: 2022-02-24 | K35: Software and Services (Primary) | L35: 1766.63 | M35: 2022-04-20 | N35: - | O35: Acquisition of Minority Stake; Cross-Border; Majority Shareholder Increasing Ownership Stake; Majority Shareholder Purchasing Remaining Shares; Squeeze Out / Short Form Merger; Tender Offer; Tender Offer (Partial Bid)
A36: 2022-04-07 | B36: CDK Global, LLC | C36: - | D36: Merger/Acquisition | E36: Closed | F36: 8340.71 | G36: Brookfield Business Corporation (TSX:BBUC) | H36: - | I36: IQTR1777417497 | J36: 2022-04-07 | K36: Software and Services (Primary) | L36: 1756.5 | M36: 2022-07-05 | N36: - | O36: Acquisition of Majority Stake; Cash Merger; Cross-Border; Going Private Transaction; Leveraged Buy Out (LBO); Squeeze Out / Short Form Merger; Tender Offer; Tender Offer (Full Bid)
A37: 2022-12-16 | B37: Vantor Parent Inc. | C37: - | D37: Merger/Acquisition | E37: Closed | F37: 6570.02 | G37: Advent International, L.P.; British Columbia Investment Management Corporation | H37: BlackRock, Inc. (NYSE:BLK); The Vanguard Group, Inc. | I37: IQTR1818826920 | J37: 2022-12-16 | K37: Software and Services (Primary) | L37: 1747 | M37: 2023-05-03 | N37: - | O37: Acquisition of Majority Stake; Cash Merger; Cross-Border; Go Shop Provision; Leveraged Buy Out (LBO)
A38: 2021-11-09 | B38: Noventiq Holdings plc | C38: - | D38: Merger/Acquisition | E38: Closed | F38: - | G38: - | H38: Softline Group | I38: IQTR1760525650 | J38: 2021-11-09 | K38: Software and Services (Primary) | L38: 1734.66 | M38: 2021-11-01 | N38: - | O38: Acquisition of Minority Stake
A39: 2025-05-27 | B39: Informatica Inc. | C39: - | D39: Merger/Acquisition | E39: Closed | F39: 10097.75 | G39: Salesforce, Inc. (NYSE:CRM) | H39: Bank of America Corporation (NYSE:BAC); Canada Pension Plan Investment Board; EvomLux S.à r.l.; Ithaca Limited; 13381986 Canada, Inc. | I39: IQTR1945143029 | J39: 2025-05-27 | K39: Software and Services (Primary) | L39: 1655.31 | M39: 2025-11-18 | N39: 280.9 | O39: Acquisition of Majority Stake; Cash Merger
A40: 2024-07-24 | B40: Exclusive Networks SA | C40: - | D40: Merger/Acquisition | E40: Closed | F40: 803.5 | G40: Clayton, Dubilier & Rice, LLC; Permira Advisers Ltd. | H40: - | I40: IQTR1888824933 | J40: 2024-07-24 | K40: Software and Services (Primary) | L40: 1613.63 | M40: 2025-02-28 | N40: - | O40: Acquisition of Minority Stake; Cash Merger; Cross-Border; Going Private Transaction; Majority Shareholder Increasing Ownership Stake; Squeeze Out / Short Form Merger; Tender Offer; Tender Offer (Full Bid)
...
